Sun 24 Jan 13:49:54 GMT 2021
Number Parameters:  1191596
Traceback (most recent call last):
  File "/cluster/home/cug/yl339/current_proj/src/train.py", line 64, in <module>
    run_training(1,params,hyperparams,save_model=True)
  File "/cluster/home/cug/yl339/current_proj/src/train.py", line 42, in run_training
    train_loss = eng.train(trainloaders,params)
  File "/cluster/home/cug/yl339/current_proj/src/utils.py", line 47, in train
    loss = self.criterion(outputs,targets,loss_params)
  File "/cluster/home/cug/yl339/current_proj/src/utils.py", line 32, in criterion
    loss = loss_fun(outputs,targets)
  File "/cluster/home/cug/yl339/anaconda2/envs/py3/lib/python3.7/site-packages/torch/nn/modules/module.py", line 532, in __call__
    result = self.forward(*input, **kwargs)
  File "/cluster/home/cug/yl339/anaconda2/envs/py3/lib/python3.7/site-packages/torch/nn/modules/loss.py", line 916, in forward
    ignore_index=self.ignore_index, reduction=self.reduction)
  File "/cluster/home/cug/yl339/anaconda2/envs/py3/lib/python3.7/site-packages/torch/nn/functional.py", line 2021, in cross_entropy
    return nll_loss(log_softmax(input, 1), target, weight, None, ignore_index, None, reduction)
  File "/cluster/home/cug/yl339/anaconda2/envs/py3/lib/python3.7/site-packages/torch/nn/functional.py", line 1838, in nll_loss
    ret = torch._C._nn.nll_loss(input, target, weight, _Reduction.get_enum(reduction), ignore_index)
RuntimeError: multi-target not supported at /opt/conda/conda-bld/pytorch_1579022060824/work/aten/src/THCUNN/generic/ClassNLLCriterion.cu:15
Sun 24 Jan 13:49:56 GMT 2021
